Workbook

Sheet System Parameters
A3: System Parameters (defined by hardware) | E3: Profiles (usage of each component mode - defined by software and usage)
B4: form the datasheets
E5: "off" | F5: "sensing" | G5: "interactive"
A6: Processor | B6: 120 | D6: 0 | E6: 0.05 | F6: 0.1
A7: Active | B7: 60 | C7: mW | D7: 0 | E7: 0.2 | F7: 0.3 | G7: 0
A8: Idle | B8: 0.28 | C8: mW | D8: 1 | E8: 0.75 | F8: 0.6 | G8: 0
A9: Sleep | B9: 1.00035 | C9: mW | E9: 0 | F9: 0 | G9: 0
A11: LED | B11: 6.6 | D11: 0 | E11: 0.03 | F11: 0.05
A12: On | B12: 5.0004 | C12: mW | E12: 0 | F12: 0 | G12: 0
A15: Sensor | B15: 57 | D15: 0 | E15: 0.05 | F15: 0.1
A16: On | B16: 0.03 | C16: mW | D16: 0 | E16: 0.95 | F16: 0.9 | G16: 0
A17: Idle | B17: 0.001 | C17: mW | D17: 1 | E17: 0 | F17: 0 | G17: 0
A18: Off | B18: 1.00045 | C18: mW | E18: 0 | F18: 0 | G18: 0
A20: Display | B20: 0 | D20: 0 | E20: 0 | F20: 0
A21: On | B21: 0 | C21: mW | D21: 0 | E21: 0 | F21: 0 | G21: 0
A22: Off (leakage) | B22: 1.0006 | C22: mW | E22: 0 | F22: 0 | G22: 0
A24: Radio | B24: 0
A25: Data Rate | B25: 350 | C25: bps | D25: 0 | E25: 1 | F25: 0.9 | G25: 0 | L25: Total power in profile (mw) | O25: Maximum Time
A26: Standby Power | B26: 1200 | C26: mW | D26: 0 | E26: 0 | F26: 0.1 | G26: 0 | L26: =E5 -> "off" | M26: =SUMPRODUCT(B7:B28, E7:E28) -> 365.2865 | N26: mW | O26: =$M$31/M26 -> 0.0085235835 | P26: hours
A27: TX Power | B27: 0 | C27: mW | D27: 1 | E27: 0 | F27: 0 | G27: 0 | L27: =F5 -> "sensing" | M27: =SUMPRODUCT(B7:B28, F7:F28) -> 459.225 | N27: mW | O27: =$M$31/M27 -> 0.0067800098 | P27: hours
A28: RX Power | B28: 10.000001 | C28: mW | E28: 0 | F28: 0 | G28: 0 | L28: =G5 -> "interactive" | M28: =SUMPRODUCT(B7:B28, G7:G28) -> 0 | N28: mW | O28: =$M$31/M28 -> #DIV/0! | P28: hours
D29: 16 | E29: 7 | F29: 1
E30: 16 | F30: 7 | G30: 1 | H30: hours/day typical usage | L30: Effective Battery Capacity
A31: Battery | B31: 2000 | M31: =B32*B33*B34 -> 3.11355 | N31: mW*h
A32: Capacity | B32: 3.7 | C32: mAh
A33: Nominal Voltage | B33: 0.85 | C33: V | L33: Days of Use | M33: =M31/(E30*M26+F30*M27+G30*M28) -> 0.00034369084 | N33: days
A34: Regulator Efficiency | B34: 0.99 | L34: Hours of Use | M34: =M33*24 -> 0.0082485802 | N34: hours
A38: REFLECTIONS : WHAT DID YOU LEARN FROM ANALYZING YOUR POWER. TALK ABOUT SOME POTENTIAL TRADEOFFS.
A39: REFLECTIONS: 1. How did I determine the "days of use" metric? My Screen Usage Load Meter is a desktop device that tracks computer usage time throughout the day. I determined that a 1-day runtime (requiring daily charging) is the optimal target because: (a) The device follows my computer's usage pattern - when I use my computer (typically 8 hours per day), the device actively monitors usage; when the computer is off, the device enters deep sleep. (b) Daily charging aligns naturally with my routine - I can charge it overnight just like my phone, ensuring it's always ready for the next day. (c) The calculated 2-day runtime with a 2000mAh battery provides a comfortable safety margin. Even if I forget to charge one night, the device will still function the next day. This margin also accounts for battery degradation over time and temperature effects that can reduce capacity by 10-20% in real-world conditions. 2. What is the optimum battery size? The optimum battery is 2000mAh LiPo (3.7V, ~$13, 35g). Here's why: A 1000mAh battery would provide only 1 day of runtime with no margin for error, making it risky. The 2000mAh battery provides 2 days of runtime, giving me flexibility and safety buffer. A 3000mAh battery would provide 3 days (unnecessary for a desk device) and adds extra weight and cost ($18, 50g). The 2000mAh hits the sweet spot - reliable 1+ day operation, affordable, and compact enough for desktop use. The stepper motor's holding current (350mW) dominates power consumption, but this is necessary for the device's function as a physical display. If I used a larger battery to avoid daily charging, I'd still need to check the device daily anyway to see the usage meter, so daily charging doesn't add inconvenience. 3. What hardware/software/cost/effort tradeoffs could improve the user experience? Highest ROI: Reduce motor holding time - currently the motor holds position continuously (350mW for 7 hours = 2450mW·h daily). By only energizing the motor when actively displaying or when user approaches (detected by distance sensor), I could reduce this by 50-70%, extending runtime from 2 to 3-4 days. Implementation: simple software change (1-2 hours). Cost: $0. Medium ROI: Reduce sensor polling frequency from 1 minute to 2 minutes. This halves sensor active time, saving ~28mW average (about 10% total consumption). Still provides adequate resolution for usage tracking. Implementation: change one constant in code (5 minutes). Cost: $0. Low ROI: Add solar panel ($15, 3 hours effort). A small 5V 100mA panel could provide ~500mW during daylight, extending runtime significantly for window-mounted installations. However, my device sits on desk without direct sunlight, making this impractical. Not worth the added complexity. Smart choice: Implement both motor optimization and sensor frequency reduction. Combined, these save ~40% power consumption, extending the 2000mAh battery runtime from 2 to 3.3 days with minimal effort and zero cost.

Sheet Sensitivity Analysis
A50: Linked Data from First Page DO NOT EDIT
A52: ='System Parameters'!A3 -> System Parameters (defined by hardware) | B52: ='System Parameters'!B3 -> 0 | C52: ='System Parameters'!C3 -> 0 | D52: ='System Parameters'!D3 -> 0 | T52: ='System Parameters'!E3 -> Profiles (usage of each component mode - defined by software and usage) | U52: ='System Parameters'!F3 -> 0 | V52: ='System Parameters'!G3 -> 0 | W52: ='System Parameters'!H3 -> 0
A53: ='System Parameters'!A4 -> 0 | B53: ='System Parameters'!B4 -> form the datasheets | C53: ='System Parameters'!C4 -> 0 | D53: ='System Parameters'!D4 -> 0 | T53: ='System Parameters'!E4 -> 0 | U53: ='System Parameters'!F4 -> 0 | V53: ='System Parameters'!G4 -> 0 | W53: ='System Parameters'!H4 -> 0
A54: ='System Parameters'!A5 -> 0 | B54: ='System Parameters'!B5 -> 0 | C54: ='System Parameters'!C5 -> 0 | D54: ='System Parameters'!D5 -> 0 | T54: ='System Parameters'!E5 -> "off" | U54: ='System Parameters'!F5 -> "sensing" | V54: ='System Parameters'!G5 -> "interactive" | W54: ='System Parameters'!H5 -> 0
A55: ='System Parameters'!A6 -> Processor | B55: ='System Parameters'!B6 -> 120 | C55: ='System Parameters'!C6 -> 0 | D55: ='System Parameters'!D6 -> 0 | T55: ='System Parameters'!E6 -> 0.05 | U55: ='System Parameters'!F6 -> 0.1 | V55: ='System Parameters'!G6 -> 0 | W55: ='System Parameters'!H6 -> 0
A56: ='System Parameters'!A7 -> Active | B56: ='System Parameters'!B7 -> 60 | C56: ='System Parameters'!C7 -> mW | D56: =$B56*0.9 -> 54 | E56: =$B56 -> 60 | F56: =$B56 -> 60 | G56: =$B56 -> 60 | H56: =$B56 -> 60 | I56: =$B56 -> 60 | J56: =$B56 -> 60 | K56: =$B56 -> 60 | L56: =$B56 -> 60 | ... O56: =$B56 -> 60 | T56: ='System Parameters'!E7 -> 0.2 | U56: ='System Parameters'!F7 -> 0.3 | V56: ='System Parameters'!G7 -> 0 | W56: ='System Parameters'!H7 -> 0
A57: ='System Parameters'!A8 -> Idle | B57: ='System Parameters'!B8 -> 0.28 | C57: ='System Parameters'!C8 -> mW | D57: =$B57 -> 0.28 | E57: =$B57*0.9 -> 0.252 | F57: =$B57 -> 0.28 | G57: =$B57 -> 0.28 | H57: =$B57 -> 0.28 | I57: =$B57 -> 0.28 | J57: =$B57 -> 0.28 | K57: =$B57 -> 0.28 | L57: =$B57 -> 0.28 | M57: =$B57 -> 0.28 | ... O57: =$B57 -> 0.28 | T57: ='System Parameters'!E8 -> 0.75 | U57: ='System Parameters'!F8 -> 0.6 | V57: ='System Parameters'!G8 -> 0 | W57: ='System Parameters'!H8 -> 0
A58: ='System Parameters'!A9 -> Sleep | B58: ='System Parameters'!B9 -> 1.00035 | C58: ='System Parameters'!C9 -> mW | D58: =$B58 -> 1.00035 | E58: =$B58 -> 1.00035 | F58: =$B58*0.9 -> 0.900315 | G58: =$B58 -> 1.00035 | H58: =$B58 -> 1.00035 | I58: =$B58 -> 1.00035 | J58: =$B58 -> 1.00035 | K58: =$B58 -> 1.00035 | L58: =$B58 -> 1.00035 | M58: =$B58 -> 1.00035 | N58: =$B58 -> 1.00035 | O58: =$B58 -> 1.00035 | T58: ='System Parameters'!E9 -> 0 | U58: ='System Parameters'!F9 -> 0 | V58: ='System Parameters'!G9 -> 0 | W58: ='System Parameters'!H9 -> 0
A59: ='System Parameters'!A10 -> 0 | B59: ='System Parameters'!B10 -> 0 | C59: ='System Parameters'!C10 -> 0 | D59: =$B59 -> 0 | E59: =$B59 -> 0 | F59: =$B59 -> 0 | G59: =$B59 -> 0 | H59: =$B59 -> 0 | I59: =$B59 -> 0 | J59: =$B59 -> 0 | K59: =$B59 -> 0 | ... O59: =$B59 -> 0 | T59: ='System Parameters'!E10 -> 0 | U59: ='System Parameters'!F10 -> 0 | V59: ='System Parameters'!G10 -> 0 | W59: ='System Parameters'!H10 -> 0
A60: ='System Parameters'!A11 -> LED | B60: ='System Parameters'!B11 -> 6.6 | C60: ='System Parameters'!C11 -> 0 | D60: =$B60 -> 6.6 | E60: =$B60 -> 6.6 | F60: =$B60 -> 6.6 | G60: =$B60 -> 6.6 | H60: =$B60 -> 6.6 | I60: =$B60 -> 6.6 | J60: =$B60 -> 6.6 | K60: =$B60 -> 6.6 | ... O60: =$B60 -> 6.6 | T60: ='System Parameters'!E11 -> 0.03 | U60: ='System Parameters'!F11 -> 0.05 | V60: ='System Parameters'!G11 -> 0 | W60: ='System Parameters'!H11 -> 0
A61: ='System Parameters'!A12 -> On | B61: ='System Parameters'!B12 -> 5.0004 | C61: ='System Parameters'!C12 -> mW | D61: =$B61 -> 5.0004 | E61: =$B61 -> 5.0004 | F61: =$B61 -> 5.0004 | G61: =$B61*0.9 -> 4.50036 | H61: =$B61 -> 5.0004 | I61: =$B61 -> 5.0004 | J61: =$B61 -> 5.0004 | K61: =$B61 -> 5.0004 | L61: =$B61 -> 5.0004 | M61: =$B61 -> 5.0004 | N61: =$B61 -> 5.0004 | O61: =$B61 -> 5.0004 | T61: ='System Parameters'!E12 -> 0 | U61: ='System Parameters'!F12 -> 0 | V61: ='System Parameters'!G12 -> 0 | W61: ='System Parameters'!H12 -> 0
A62: ='System Parameters'!A13 -> 0 | B62: ='System Parameters'!B13 -> 0 | C62: ='System Parameters'!C13 -> 0 | D62: =$B62 -> 0 | E62: =$B62 -> 0 | F62: =$B62 -> 0 | G62: =$B62 -> 0 | H62: =$B62 -> 0 | I62: =$B62 -> 0 | J62: =$B62 -> 0 | K62: =$B62 -> 0 | ... O62: =$B62 -> 0 | T62: ='System Parameters'!E13 -> 0 | U62: ='System Parameters'!F13 -> 0 | V62: ='System Parameters'!G13 -> 0 | W62: ='System Parameters'!H13 -> 0
A63: ='System Parameters'!A14 -> 0 | B63: ='System Parameters'!B14 -> 0 | C63: ='System Parameters'!C14 -> 0 | D63: =$B63 -> 0 | E63: =$B63 -> 0 | F63: =$B63 -> 0 | G63: =$B63 -> 0 | H63: =$B63 -> 0 | I63: =$B63 -> 0 | J63: =$B63 -> 0 | K63: =$B63 -> 0 | ... O63: =$B63 -> 0 | T63: ='System Parameters'!E14 -> 0 | U63: ='System Parameters'!F14 -> 0 | V63: ='System Parameters'!G14 -> 0 | W63: ='System Parameters'!H14 -> 0
A64: ='System Parameters'!A15 -> Sensor | B64: ='System Parameters'!B15 -> 57 | C64: ='System Parameters'!C15 -> 0 | D64: =$B64 -> 57 | E64: =$B64 -> 57 | F64: =$B64 -> 57 | G64: =$B64 -> 57 | H64: =$B64 -> 57 | I64: =$B64 -> 57 | J64: =$B64 -> 57 | K64: =$B64 -> 57 | ... O64: =$B64 -> 57 | T64: ='System Parameters'!E15 -> 0.05 | U64: ='System Parameters'!F15 -> 0.1 | V64: ='System Parameters'!G15 -> 0 | W64: ='System Parameters'!H15 -> 0
A65: ='System Parameters'!A16 -> On | B65: ='System Parameters'!B16 -> 0.03 | C65: ='System Parameters'!C16 -> mW | D65: =$B65 -> 0.03 | E65: =$B65 -> 0.03 | F65: =$B65 -> 0.03 | G65: =$B65 -> 0.03 | H65: =$B65*0.9 -> 0.027 | I65: =$B65 -> 0.03 | J65: =$B65 -> 0.03 | K65: =$B65 -> 0.03 | L65: =$B65 -> 0.03 | M65: =$B65 -> 0.03 | N65: =$B65 -> 0.03 | O65: =$B65 -> 0.03 | T65: ='System Parameters'!E16 -> 0.95 | U65: ='System Parameters'!F16 -> 0.9 | V65: ='System Parameters'!G16 -> 0 | W65: ='System Parameters'!H16 -> 0
A66: ='System Parameters'!A17 -> Idle | B66: ='System Parameters'!B17 -> 0.001 | C66: ='System Parameters'!C17 -> mW | D66: =$B66 -> 0.001 | E66: =$B66 -> 0.001 | F66: =$B66 -> 0.001 | G66: =$B66 -> 0.001 | H66: =$B66 -> 0.001 | I66: =$B66*0.9 -> 0.0009 | J66: =$B66 -> 0.001 | K66: =$B66 -> 0.001 | L66: =$B66 -> 0.001 | M66: =$B66 -> 0.001 | N66: =$B66 -> 0.001 | O66: =$B66 -> 0.001 | T66: ='System Parameters'!E17 -> 0 | U66: ='System Parameters'!F17 -> 0 | V66: ='System Parameters'!G17 -> 0 | W66: ='System Parameters'!H17 -> 0
A67: ='System Parameters'!A18 -> Off | B67: ='System Parameters'!B18 -> 1.00045 | C67: ='System Parameters'!C18 -> mW | D67: =$B67 -> 1.00045 | E67: =$B67 -> 1.00045 | F67: =$B67 -> 1.00045 | G67: =$B67 -> 1.00045 | H67: =$B67 -> 1.00045 | I67: =$B67 -> 1.00045 | J67: =$B67*0.9 -> 0.900405 | K67: =$B67 -> 1.00045 | L67: =$B67 -> 1.00045 | M67: =$B67 -> 1.00045 | N67: =$B67 -> 1.00045 | O67: =$B67 -> 1.00045 | T67: ='System Parameters'!E18 -> 0 | U67: ='System Parameters'!F18 -> 0 | V67: ='System Parameters'!G18 -> 0 | W67: ='System Parameters'!H18 -> 0
A68: ='System Parameters'!A19 -> 0 | B68: ='System Parameters'!B19 -> 0 | C68: ='System Parameters'!C19 -> 0 | D68: =$B68 -> 0 | E68: =$B68 -> 0 | F68: =$B68 -> 0 | G68: =$B68 -> 0 | H68: =$B68 -> 0 | I68: =$B68 -> 0 | J68: =$B68 -> 0 | K68: =$B68 -> 0 | ... O68: =$B68 -> 0 | T68: ='System Parameters'!E19 -> 0 | U68: ='System Parameters'!F19 -> 0 | V68: ='System Parameters'!G19 -> 0 | W68: ='System Parameters'!H19 -> 0
A69: ='System Parameters'!A20 -> Display | B69: ='System Parameters'!B20 -> 0 | C69: ='System Parameters'!C20 -> 0 | D69: =$B69 -> 0 | E69: =$B69 -> 0 | F69: =$B69 -> 0 | G69: =$B69 -> 0 | H69: =$B69 -> 0 | I69: =$B69 -> 0 | J69: =$B69 -> 0 | K69: =$B69 -> 0 | ... O69: =$B69 -> 0 | T69: ='System Parameters'!E20 -> 0 | U69: ='System Parameters'!F20 -> 0 | V69: ='System Parameters'!G20 -> 0 | W69: ='System Parameters'!H20 -> 0
A70: ='System Parameters'!A21 -> On | B70: ='System Parameters'!B21 -> 0 | C70: ='System Parameters'!C21 -> mW | D70: =$B70 -> 0 | E70: =$B70 -> 0 | F70: =$B70 -> 0 | G70: =$B70 -> 0 | H70: =$B70 -> 0 | I70: =$B70 -> 0 | J70: =$B70 -> 0 | K70: =$B70*0.9 -> 0 | L70: =$B70 -> 0 | M70: =$B70 -> 0 | N70: =$B70 -> 0 | O70: =$B70 -> 0 | T70: ='System Parameters'!E21 -> 0 | U70: ='System Parameters'!F21 -> 0 | V70: ='System Parameters'!G21 -> 0 | W70: ='System Parameters'!H21 -> 0
A71: ='System Parameters'!A22 -> Off (leakage) | B71: ='System Parameters'!B22 -> 1.0006 | C71: ='System Parameters'!C22 -> mW | D71: =$B71 -> 1.0006 | E71: =$B71 -> 1.0006 | F71: =$B71 -> 1.0006 | G71: =$B71 -> 1.0006 | H71: =$B71 -> 1.0006 | I71: =$B71 -> 1.0006 | J71: =$B71 -> 1.0006 | K71: =$B71 -> 1.0006 | L71: =$B71*0.9 -> 0.90054 | M71: =$B71 -> 1.0006 | N71: =$B71 -> 1.0006 | O71: =$B71 -> 1.0006 | T71: ='System Parameters'!E22 -> 0 | U71: ='System Parameters'!F22 -> 0 | V71: ='System Parameters'!G22 -> 0 | W71: ='System Parameters'!H22 -> 0
A72: ='System Parameters'!A23 -> 0 | B72: ='System Parameters'!B23 -> 0 | C72: ='System Parameters'!C23 -> 0 | D72: =$B72 -> 0 | E72: =$B72 -> 0 | F72: =$B72 -> 0 | G72: =$B72 -> 0 | H72: =$B72 -> 0 | I72: =$B72 -> 0 | J72: =$B72 -> 0 | K72: =$B72 -> 0 | ... O72: =$B72 -> 0 | T72: ='System Parameters'!E23 -> 0 | U72: ='System Parameters'!F23 -> 0 | V72: ='System Parameters'!G23 -> 0 | W72: ='System Parameters'!H23 -> 0
A73: ='System Parameters'!A24 -> Radio | B73: ='System Parameters'!B24 -> 0 | C73: ='System Parameters'!C24 -> 0 | D73: =$B73 -> 0 | E73: =$B73 -> 0 | F73: =$B73 -> 0 | G73: =$B73 -> 0 | H73: =$B73 -> 0 | I73: =$B73 -> 0 | J73: =$B73 -> 0 | K73: =$B73 -> 0 | ... O73: =$B73 -> 0 | T73: ='System Parameters'!E24 -> 0 | U73: ='System Parameters'!F24 -> 0 | V73: ='System Parameters'!G24 -> 0 | W73: ='System Parameters'!H24 -> 0
A74: ='System Parameters'!A26 -> Standby Power | B74: ='System Parameters'!B26 -> 1200 | C74: ='System Parameters'!C26 -> mW | D74: =$B74 -> 1200 | E74: =$B74 -> 1200 | F74: =$B74 -> 1200 | G74: =$B74 -> 1200 | H74: =$B74 -> 1200 | I74: =$B74 -> 1200 | J74: =$B74 -> 1200 | K74: =$B74 -> 1200 | L74: =$B74 -> 1200 | M74: =$B74*0.9 -> 1080 | N74: =$B74 -> 1200 | O74: =$B74 -> 1200 | T74: ='System Parameters'!E26 -> 0 | U74: ='System Parameters'!F26 -> 0.1 | V74: ='System Parameters'!G26 -> 0 | W74: ='System Parameters'!H26 -> 0
A75: ='System Parameters'!A27 -> TX Power | B75: ='System Parameters'!B27 -> 0 | C75: ='System Parameters'!C27 -> mW | D75: =$B75 -> 0 | E75: =$B75 -> 0 | F75: =$B75 -> 0 | G75: =$B75 -> 0 | H75: =$B75 -> 0 | I75: =$B75 -> 0 | J75: =$B75 -> 0 | K75: =$B75 -> 0 | ... M75: =$B75 -> 0 | N75: =$B75*0.9 -> 0 | O75: =$B75 -> 0 | T75: ='System Parameters'!E27 -> 0 | U75: ='System Parameters'!F27 -> 0 | V75: ='System Parameters'!G27 -> 0 | W75: ='System Parameters'!H27 -> 0
A76: ='System Parameters'!A28 -> RX Power | B76: ='System Parameters'!B28 -> 10.000001 | C76: ='System Parameters'!C28 -> mW | D76: =$B76 -> 10.000001 | E76: =$B76 -> 10.000001 | F76: =$B76 -> 10.000001 | G76: =$B76 -> 10.000001 | H76: =$B76 -> 10.000001 | I76: =$B76 -> 10.000001 | J76: =$B76 -> 10.000001 | K76: =$B76 -> 10.000001 | ... N76: =$B76 -> 10.000001 | O76: =$B76*0.9 -> 9.0000009 | T76: ='System Parameters'!E28 -> 0 | U76: ='System Parameters'!F28 -> 0 | V76: ='System Parameters'!G28 -> 0 | W76: ='System Parameters'!H28 -> 0
A77: ='System Parameters'!A29 -> 0 | B77: ='System Parameters'!B29 -> 0 | C77: ='System Parameters'!C29 -> 0 | D77: ='System Parameters'!D29 -> 16 | T77: ='System Parameters'!E29 -> 7 | U77: ='System Parameters'!F29 -> 1 | V77: ='System Parameters'!G29 -> 0 | W77: ='System Parameters'!H29 -> 0
A78: ='System Parameters'!A30 -> 0 | B78: ='System Parameters'!B30 -> 0 | C78: ='System Parameters'!C30 -> 0 | D78: ='System Parameters'!D30 -> 0 | T78: ='System Parameters'!E30 -> 16 | U78: ='System Parameters'!F30 -> 7 | V78: ='System Parameters'!G30 -> 1 | W78: ='System Parameters'!H30 -> hours/day typical usage
A79: ='System Parameters'!A31 -> Battery | B79: ='System Parameters'!B31 -> 2000 | C79: ='System Parameters'!C31 -> 0 | D79: ='System Parameters'!D31 -> 0 | T79: ='System Parameters'!E31 -> 0 | U79: ='System Parameters'!F31 -> 0 | V79: ='System Parameters'!G31 -> 0 | W79: ='System Parameters'!H31 -> 0
A80: ='System Parameters'!A32 -> Capacity | B80: ='System Parameters'!B32 -> 3.7 | C80: ='System Parameters'!C32 -> mAh | D80: ='System Parameters'!D32 -> 0 | T80: ='System Parameters'!E32 -> 0 | U80: ='System Parameters'!F32 -> 0 | V80: ='System Parameters'!G32 -> 0 | W80: ='System Parameters'!H32 -> 0
A81: ='System Parameters'!A33 -> Nominal Voltage | B81: ='System Parameters'!B33 -> 0.85 | C81: ='System Parameters'!C33 -> V | D81: ='System Parameters'!D33 -> 0 | T81: ='System Parameters'!E33 -> 0 | U81: ='System Parameters'!F33 -> 0 | V81: ='System Parameters'!G33 -> 0 | W81: ='System Parameters'!H33 -> 0
A82: ='System Parameters'!A34 -> Regulator Efficiency | B82: ='System Parameters'!B34 -> 0.99 | C82: ='System Parameters'!C34 -> 0 | D82: ='System Parameters'!D34 -> 0 | T82: ='System Parameters'!E34 -> 0 | U82: ='System Parameters'!F34 -> 0 | V82: ='System Parameters'!G34 -> 0 | W82: ='System Parameters'!H34 -> 0
A83: ='System Parameters'!A35 -> 0 | B83: ='System Parameters'!B35 -> 0 | C83: ='System Parameters'!C35 -> 0 | D83: ='System Parameters'!D35 -> 0 | O83: ='System Parameters'!E35 -> 0 | P83: ='System Parameters'!F35 -> 0 | Q83: ='System Parameters'!G35 -> 0 | R83: ='System Parameters'!H35 -> 0 | S83: ='System Parameters'!I35 -> 0 | T83: ='System Parameters'!J35 -> 0 | U83: =#REF! -> #REF! | V83: =#REF! -> #REF!
A84: ='System Parameters'!A36 -> 0 | B84: ='System Parameters'!B36 -> 0 | C84: ='System Parameters'!C36 -> 0 | D84: ='System Parameters'!D36 -> 0 | O84: ='System Parameters'!E36 -> 0 | P84: ='System Parameters'!F36 -> 0 | Q84: ='System Parameters'!G36 -> 0 | R84: ='System Parameters'!H36 -> 0 | S84: ='System Parameters'!I36 -> 0 | T84: ='System Parameters'!J36 -> 0 | U84: =#REF! -> #REF! | V84: =#REF! -> #REF!
A85: ='System Parameters'!A39 -> REFLECTIONS: 1. How did I determine the "days of use" metric? My Screen Usage Load Meter is a desktop device that tracks computer usage time throughout the day. I determined that a 1-day runtime (requiring daily charging) is the optimal target because: (a) The device follows my computer's usage pattern - when I use my computer (typically 8 hours per day), the device actively monitors usage; when the computer is off, the device enters deep sleep. (b) Daily charging aligns naturally with my routine - I can charge it overnight just like my phone, ensuring it's always ready for the next day. (c) The calculated 2-day runtime with a 2000mAh battery provides a comfortable safety margin. Even if I forget to charge one night, the device will still function the next day. This margin also accounts for battery degradation over time and temperature effects that can reduce capacity by 10-20% in real-world conditions. 2. What is the optimum battery size? The optimum battery is 2000mAh LiPo (3.7V, ~$13, 35g). Here's why: A 1000mAh battery would provide only 1 day of runtime with no margin for error, making it risky. The 2000mAh battery provides 2 days of runtime, giving me flexibility and safety buffer. A 3000mAh battery would provide 3 days (unnecessary for a desk device) and adds extra weight and cost ($18, 50g). The 2000mAh hits the sweet spot - reliable 1+ day operation, affordable, and compact enough for desktop use. The stepper motor's holding current (350mW) dominates power consumption, but this is necessary for the device's function as a physical display. If I used a larger battery to avoid daily charging, I'd still need to check the device daily anyway to see the usage meter, so daily charging doesn't add inconvenience. 3. What hardware/software/cost/effort tradeoffs could improve the user experience? Highest ROI: Reduce motor holding time - currently the motor holds position continuously (350mW for 7 hours = 2450mW·h daily). By only energizing the motor when actively displaying or when user approaches (detected by distance sensor), I could reduce this by 50-70%, extending runtime from 2 to 3-4 days. Implementation: simple software change (1-2 hours). Cost: $0. Medium ROI: Reduce sensor polling frequency from 1 minute to 2 minutes. This halves sensor active time, saving ~28mW average (about 10% total consumption). Still provides adequate resolution for usage tracking. Implementation: change one constant in code (5 minutes). Cost: $0. Low ROI: Add solar panel ($15, 3 hours effort). A small 5V 100mA panel could provide ~500mW during daylight, extending runtime significantly for window-mounted installations. However, my device sits on desk without direct sunlight, making this impractical. Not worth the added complexity. Smart choice: Implement both motor optimization and sensor frequency reduction. Combined, these save ~40% power consumption, extending the 2000mAh battery runtime from 2 to 3.3 days with minimal effort and zero cost. | B85: ='System Parameters'!K24 -> 0 | C85: ='System Parameters'!L24 -> 0 | D85: ='System Parameters'!M24 -> 0 | O85: ='System Parameters'!N24 -> 0 | P85: ='System Parameters'!O24 -> 0 | Q85: ='System Parameters'!P24 -> 0 | R85: ='System Parameters'!Q24 -> 0 | S85: ='System Parameters'!I37 -> 0 | T85: ='System Parameters'!J37 -> 0 | U85: =#REF! -> #REF! | V85: =#REF! -> #REF!
A86: ='System Parameters'!A38 -> REFLECTIONS : WHAT DID YOU LEARN FROM ANALYZING YOUR POWER. TALK ABOUT SOME POTENTIAL TRADEOFFS. | B86: ='System Parameters'!K25 -> 0 | C86: =#REF! -> #REF! | D86: =#REF! -> #REF! | O86: =#REF! -> #REF! | P86: =#REF! -> #REF! | Q86: =#REF! -> #REF! | R86: ='System Parameters'!Q25 -> 0 | S86: ='System Parameters'!I38 -> 0 | T86: ='System Parameters'!J38 -> 0 | U86: =#REF! -> #REF! | V86: =#REF! -> #REF!
A87: ='System Parameters'!L25 -> Total power in profile (mw) | B87: ='System Parameters'!M25 -> 0 | C87: ='System Parameters'!N25 -> 0 | R87: ='System Parameters'!Q26 -> 0 | S87: ='System Parameters'!I39 -> 0 | T87: ='System Parameters'!J39 -> 0 | U87: ='System Parameters'!K39 -> 0 | V87: ='System Parameters'!L39 -> 0
A88: ='System Parameters'!L26 -> "off" | B88: =SUMPRODUCT(B56:B76, $T56:$T76) -> 15.2865 | C88: ='System Parameters'!N26 -> mW | D88: =SUMPRODUCT(D56:D76, $T56:$T76) -> 14.0865 | E88: =SUMPRODUCT(E56:E76, $T56:$T76) -> 15.2655 | F88: =SUMPRODUCT(F56:F76, $T56:$T76) -> 15.2865 | G88: =SUMPRODUCT(G56:G76, $T56:$T76) -> 15.2865 | H88: =SUMPRODUCT(H56:H76, $T56:$T76) -> 15.28365 | I88: =SUMPRODUCT(I56:I76, $T56:$T76) -> 15.2865 | J88: =SUMPRODUCT(J56:J76, $T56:$T76) -> 15.2865 | K88: =SUMPRODUCT(K56:K76, $T56:$T76) -> 15.2865 | ... O88: =SUMPRODUCT(O56:O76, $T56:$T76) -> 15.2865 | R88: ='System Parameters'!Q27 -> 0 | S88: ='System Parameters'!I40 -> 0 | T88: ='System Parameters'!J40 -> 0 | U88: ='System Parameters'!K40 -> 0 | V88: ='System Parameters'!L40 -> 0
A89: ='System Parameters'!L27 -> "sensing" | B89: =SUMPRODUCT(B56:B76,$U56:$U76) -> 144.225 | C89: ='System Parameters'!N27 -> mW | D89: =SUMPRODUCT(D56:D76,$U56:$U76) -> 142.425 | E89: =SUMPRODUCT(E56:E76,$U56:$U76) -> 144.2082 | F89: =SUMPRODUCT(F56:F76,$U56:$U76) -> 144.225 | G89: =SUMPRODUCT(G56:G76,$U56:$U76) -> 144.225 | H89: =SUMPRODUCT(H56:H76,$U56:$U76) -> 144.2223 | I89: =SUMPRODUCT(I56:I76,$U56:$U76) -> 144.225 | J89: =SUMPRODUCT(J56:J76,$U56:$U76) -> 144.225 | K89: =SUMPRODUCT(K56:K76,$U56:$U76) -> 144.225 | ... O89: =SUMPRODUCT(O56:O76,$U56:$U76) -> 144.225 | R89: ='System Parameters'!Q28 -> 0 | S89: ='System Parameters'!I41 -> 0 | T89: ='System Parameters'!J41 -> 0 | U89: ='System Parameters'!K41 -> 0 | V89: ='System Parameters'!L41 -> 0
A90: ='System Parameters'!L28 -> "interactive" | B90: =SUMPRODUCT(B56:B76, $V56:$V76) -> 0 | C90: ='System Parameters'!N28 -> mW | D90: =SUMPRODUCT(D56:D76, $V56:$V76) -> 0 | E90: =SUMPRODUCT(E56:E76, $V56:$V76) -> 0 | F90: =SUMPRODUCT(F56:F76, $V56:$V76) -> 0 | G90: =SUMPRODUCT(G56:G76, $V56:$V76) -> 0 | H90: =SUMPRODUCT(H56:H76, $V56:$V76) -> 0 | I90: =SUMPRODUCT(I56:I76, $V56:$V76) -> 0 | J90: =SUMPRODUCT(J56:J76, $V56:$V76) -> 0 | K90: =SUMPRODUCT(K56:K76, $V56:$V76) -> 0 | ... O90: =SUMPRODUCT(O56:O76, $V56:$V76) -> 0 | R90: ='System Parameters'!Q29 -> 0 | S90: ='System Parameters'!I42 -> 0 | T90: ='System Parameters'!J42 -> 0 | U90: ='System Parameters'!K42 -> 0 | V90: ='System Parameters'!L42 -> 0
...
